File: POL_Tracao_Idento1_1.csv
Position (mm);Force (N);Strain (%);Time (min)
0,00;0,00;-0,000333;0,00407
0,00195;0,00;-0,000116;0,00490
0,00511;1,67;0,000698;0,00573
0,00931;2,76;0,00194;0,00656
0,0142;5,00;0,00321;0,00739
0,0182;5,28;0,00456;0,00822
0,0228;6,67;0,00577;0,00905
0,0268;8,33;0,00706;0,00988
0,0307;10,0;0,00837;0,0107
0,0347;11,2;0,00953;0,0115
0,0393;11,7;0,0108;0,0124
0,0436;13,3;0,0120;0,0132
0,0476;15,0;0,0134;0,0140
0,0520;15,8;0,0147;0,0149
0,0561;16,7;0,0159;0,0157
0,0600;18,3;0,0171;0,0165
0,0639;20,0;0,0184;0,0174
0,0687;20,0;0,0197;0,0182
0,0723;21,7;0,0209;0,0190
0,0770;23,3;0,0221;0,0198
0,0806;24,6;0,0234;0,0207
0,0850;25,5;0,0246;0,0215
0,0893;26,7;0,0259;0,0223
0,0936;28,3;0,0271;0,0232
0,0972;29,6;0,0284;0,0240
0,102;30,4;0,0296;0,0248
0,106;31,7;0,0309;0,0257
0,110;33,2;0,0321;0,0265
0,114;34,4;0,0335;0,0273
0,118;35,1;0,0347;0,0281
0,122;36,7;0,0360;0,0290
0,127;38,3;0,0373;0,0298
0,131;39,4;0,0385;0,0306
0,135;40,3;0,0399;0,0315
0,139;41,7;0,0411;0,0323
0,143;43,3;0,0425;0,0331
0,147;44,4;0,0438;0,0340
0,151;46,7;0,0451;0,0348
0,156;47,6;0,0464;0,0356
0,159;48,5;0,0478;0,0364
0,164;50,0;0,0491;0,0373
0,168;51,7;0,0504;0,0381
0,172;52,6;0,0518;0,0389
0,176;53,4;0,0531;0,0398
0,181;55,9;0,0545;0,0406
0,184;56,7;0,0559;0,0414
0,189;57,5;0,0572;0,0423
0,194;59,9;0,0586;0,0431
0,197;60,7;0,0599;0,0439
0,201;62,2;0,0613;0,0448
0,205;63,3;0,0627;0,0456
0,209;65,0;0,0640;0,0464
0,214;66,7;0,0653;0,0472
0,218;68,2;0,0667;0,0481
0,222;70,0;0,0681;0,0489
0,226;70,0;0,0696;0,0497
0,230;72,3;0,0710;0,0506
0,235;73,3;0,0724;0,0514
0,239;75,6;0,0739;0,0522
0,243;76,7;0,0752;0,0531
0,247;78,3;0,0767;0,0539
0,251;79,7;0,0780;0,0547
0,255;81,7;0,0795;0,0555
0,259;83,0;0,0808;0,0564
0,263;85,0;0,0824;0,0572
0,268;86,3;0,0838;0,0580
0,272;87,6;0,0852;0,0589
0,276;88,9;0,0867;0,0597
0,280;90,0;0,0881;0,0605
0,284;92,9;0,0897;0,0614
0,288;93,6;0,0910;0,0622
0,292;95,0;0,0925;0,0630
0,297;96,7;0,0940;0,0638
0,301;97,8;0,0955;0,0647
0,305;98,7;0,0969;0,0655
0,309;101;0,0983;0,0663
0,313;103;0,0999;0,0672
0,317;104;0,101;0,0680
0,322;105;0,103;0,0688
0,326;108;0,104;0,0697
0,330;109;0,106;0,0705
0,334;111;0,107;0,0713
0,338;112;0,109;0,0721
0,342;114;0,110;0,0730
0,346;115;0,112;0,0738
0,351;118;0,114;0,0746
0,355;119;0,115;0,0755
0,359;121;0,117;0,0763
0,363;122;0,118;0,0771
0,367;124;0,120;0,0780
0,371;125;0,121;0,0788
0,375;127;0,123;0,0796
0,379;130;0,125;0,0804
0,384;131;0,126;0,0813
0,388;133;0,128;0,0821
0,392;136;0,129;0,0829
0,396;137;0,131;0,0838
0,400;138;0,133;0,0846
0,405;140;0,134;0,0854
0,409;142;0,136;0,0863
0,413;143;0,137;0,0871
0,417;146;0,139;0,0879
0,422;148;0,141;0,0887
0,425;149;0,143;0,0896
0,430;152;0,144;0,0904
0,434;152;0,146;0,0912
0,438;155;0,148;0,0921
0,442;157;0,149;0,0929
0,446;158;0,151;0,0937
0,450;161;0,153;0,0946
0,454;162;0,154;0,0954
0,458;165;0,156;0,0962
0,463;167;0,158;0,0971
0,467;168;0,159;0,0979
0,471;171;0,161;0,0987
0,475;172;0,163;0,0995
0,479;173;0,165;0,100
0,484;175;0,166;0,101
0,488;178;0,168;0,102
0,492;180;0,170;0,103
0,496;183;0,172;0,104
0,500;185;0,173;0,105
0,504;186;0,175;0,105
0,508;188;0,177;0,106
0,512;191;0,179;0,107
0,516;193;0,181;0,108
0,520;195;0,182;0,109
0,525;197;0,184;0,110
0,528;199;0,186;0,110
0,533;202;0,188;0,111
0,537;203;0,190;0,112
0,542;205;0,192;0,113
0,545;207;0,194;0,114
0,550;209;0,195;0,114
0,553;212;0,197;0,115
0,558;214;0,199;0,116
0,562;217;0,201;0,117
0,567;218;0,203;0,118
0,570;220;0,205;0,119
0,575;223;0,207;0,119
0,579;225;0,208;0,120
0,583;228;0,210;0,121
0,587;228;0,212;0,122
0,591;231;0,214;0,123
0,596;233;0,216;0,124
0,600;236;0,218;0,124
0,604;238;0,220;0,125
0,608;240;0,222;0,126
0,612;242;0,224;0,127
0,616;244;0,226;0,128
0,621;247;0,228;0,129
0,625;250;0,229;0,129
0,629;251;0,231;0,130
0,633;253;0,233;0,131
0,637;257;0,235;0,132
0,641;259;0,237;0,133
0,646;260;0,239;0,134
0,649;262;0,241;0,134
0,654;265;0,243;0,135
0,658;267;0,245;0,136
0,662;270;0,247;0,137
0,666;272;0,249;0,138
0,671;275;0,251;0,139
0,674;277;0,253;0,139
0,679;278;0,255;0,140
0,683;281;0,257;0,141
0,687;283;0,259;0,142
0,691;286;0,261;0,143
0,695;288;0,263;0,144
0,699;291;0,265;0,144
0,703;293;0,267;0,145
0,707;296;0,269;0,146
0,711;298;0,271;0,147
0,716;300;0,273;0,148
0,720;303;0,275;0,149
0,724;305;0,278;0,149
0,729;308;0,280;0,150
0,733;310;0,282;0,151
0,736;312;0,284;0,152
0,741;315;0,286;0,153
0,745;316;0,288;0,154
0,749;320;0,290;0,154
0,753;323;0,292;0,155
0,757;324;0,294;0,156
0,761;326;0,296;0,157
0,766;329;0,298;0,158
0,770;331;0,300;0,158
0,774;334;0,303;0,159
0,778;335;0,305;0,160
0,782;339;0,307;0,161
0,786;343;0,309;0,162
0,790;344;0,311;0,163
0,795;347;0,313;0,163
0,799;349;0,316;0,164
0,803;351;0,318;0,165
0,807;354;0,320;0,166
0,812;358;0,322;0,167
0,816;360;0,324;0,168
0,819;362;0,326;0,168
0,824;365;0,328;0,169
0,828;367;0,330;0,170
0,832;370;0,333;0,171
0,836;372;0,335;0,172
0,840;373;0,337;0,173
0,845;376;0,339;0,173
0,849;378;0,341;0,174
0,853;382;0,343;0,175
0,857;383;0,345;0,176
0,862;387;0,348;0,177
0,865;390;0,350;0,178
0,869;392;0,352;0,178
0,874;393;0,354;0,179
0,878;397;0,356;0,180
0,882;400;0,359;0,181
0,886;402;0,361;0,182
0,890;405;0,363;0,183
0,895;407;0,365;0,183
0,899;410;0,367;0,184
0,903;412;0,370;0,185
0,907;415;0,372;0,186
0,911;417;0,374;0,187
0,916;420;0,376;0,188
0,919;422;0,379;0,188
0,924;425;0,381;0,189
0,928;427;0,383;0,190
0,932;430;0,385;0,191
0,936;432;0,387;0,192
0,940;436;0,390;0,193
0,944;437;0,392;0,193
0,948;440;0,394;0,194
0,952;443;0,396;0,195
0,956;445;0,398;0,196
0,960;449;0,401;0,197
0,965;451;0,403;0,198
0,969;454;0,405;0,198
0,973;456;0,407;0,199
0,977;458;0,410;0,200
0,981;461;0,412;0,201
0,985;463;0,414;0,202
0,990;466;0,416;0,202
0,994;468;0,419;0,203
0,998;471;0,421;0,204
1,00;473;0,423;0,205
1,01;476;0,425;0,206
1,01;478;0,427;0,207
1,01;481;0,430;0,207
1,02;483;0,432;0,208
1,02;486;0,434;0,209
1,03;488;0,436;0,210
1,03;491;0,439;0,211
1,04;493;0,441;0,212
1,04;497;0,443;0,212
1,04;498;0,445;0,213
1,05;501;0,448;0,214
1,05;505;0,450;0,215
1,06;507;0,452;0,216
1,06;510;0,454;0,217
1,06;512;0,457;0,217
1,07;515;0,459;0,218
1,07;517;0,461;0,219
1,08;520;0,463;0,220
1,08;522;0,466;0,221
1,09;525;0,468;0,222
1,09;527;0,470;0,222
1,09;530;0,473;0,223
1,10;532;0,475;0,224
1,10;535;0,477;0,225
1,11;538;0,479;0,226
1,11;540;0,482;0,227
1,11;542;0,484;0,227
1,12;546;0,486;0,228
1,12;548;0,489;0,229
1,13;551;0,491;0,230
1,13;554;0,493;0,231
1,14;556;0,495;0,232
1,14;559;0,498;0,232
1,14;561;0,500;0,233
1,15;564;0,502;0,234
1,15;566;0,505;0,235
1,16;569;0,507;0,236
1,16;571;0,509;0,237
1,16;574;0,511;0,237
1,17;576;0,514;0,238
1,17;580;0,516;0,239
1,18;583;0,519;0,240
1,18;585;0,521;0,241
1,18;588;0,523;0,242
1,19;590;0,525;0,242
1,19;593;0,528;0,243
1,20;595;0,530;0,244
1,20;598;0,533;0,245
1,21;601;0,535;0,246
1,21;604;0,537;0,246
1,21;606;0,540;0,247
1,22;609;0,542;0,248
1,22;612;0,544;0,249
1,23;614;0,547;0,250
1,23;617;0,549;0,251
1,23;619;0,551;0,251
1,24;622;0,554;0,252
1,24;624;0,556;0,253
1,25;627;0,559;0,254
1,25;629;0,561;0,255
1,25;632;0,563;0,256
1,26;635;0,566;0,256
1,26;638;0,568;0,257
1,27;639;0,570;0,258
1,27;642;0,573;0,259
1,28;646;0,575;0,260
1,28;648;0,578;0,261
1,28;651;0,580;0,261
1,29;653;0,582;0,262
1,29;656;0,585;0,263
1,30;658;0,587;0,264
1,30;661;0,590;0,265
1,30;663;0,592;0,266
1,31;667;0,594;0,266
1,31;670;0,597;0,267
1,32;672;0,599;0,268
1,32;675;0,601;0,269
1,33;677;0,604;0,270
1,33;681;0,606;0,271
1,33;682;0,609;0,271
1,34;685;0,611;0,272
1,34;689;0,614;0,273
1,35;691;0,616;0,274
1,35;694;0,618;0,275
1,35;696;0,621;0,276
1,36;699;0,623;0,276
1,36;702;0,626;0,277
1,37;704;0,628;0,278
1,37;706;0,630;0,279
1,38;709;0,633;0,280
1,38;711;0,635;0,281
1,38;714;0,637;0,281
1,39;718;0,640;0,282
1,39;720;0,642;0,283
1,40;723;0,645;0,284
1,40;725;0,647;0,285
1,40;728;0,650;0,285
1,41;730;0,652;0,286
1,41;733;0,654;0,287
1,42;735;0,657;0,288
1,42;738;0,659;0,289
1,43;740;0,662;0,290
1,43;743;0,664;0,290
1,43;747;0,667;0,291
1,44;749;0,669;0,292
1,44;752;0,672;0,293
1,45;754;0,674;0,294
1,45;757;0,676;0,295
1,45;759;0,679;0,295
1,46;761;0,681;0,296
1,46;764;0,684;0,297
1,47;768;0,686;0,298
1,47;771;0,688;0,299
1,48;773;0,691;0,300
1,48;776;0,693;0,300
1,48;778;0,696;0,301
1,49;781;0,698;0,302
1,49;783;0,701;0,303
1,50;786;0,703;0,304
1,50;788;0,706;0,305
1,50;791;0,708;0,305
1,51;793;0,710;0,306
1,51;797;0,713;0,307
1,52;800;0,715;0,308
1,52;802;0,718;0,309
1,53;805;0,720;0,310
1,53;807;0,723;0,310
1,53;810;0,725;0,311
1,54;812;0,728;0,312
1,54;815;0,730;0,313
1,55;818;0,733;0,314
1,55;821;0,735;0,315
1,55;823;0,738;0,315
1,56;826;0,740;0,316
1,56;829;0,743;0,317
1,57;831;0,745;0,318
1,57;833;0,747;0,319
1,57;836;0,750;0,320
1,58;839;0,752;0,320
1,58;841;0,755;0,321
1,59;844;0,757;0,322
1,59;846;0,760;0,323
1,60;849;0,762;0,324
1,60;853;0,765;0,325
1,60;855;0,767;0,325
1,61;858;0,770;0,326
1,61;860;0,772;0,327
1,62;863;0,775;0,328
1,62;865;0,777;0,329
1,63;868;0,780;0,329
1,63;870;0,782;0,330
1,63;873;0,785;0,331
1,64;875;0,787;0,332
1,64;878;0,790;0,333
1,65;882;0,792;0,334
1,65;884;0,795;0,334
1,65;887;0,797;0,335
1,66;892;0,800;0,337
1,66;892;0,800;0,337
1,67;894;0,800;0,338
1,67;897;0,800;0,339
1,67;899;0,800;0,340
1,68;901;0,800;0,340
1,68;905;0,800;0,341
1,69;908;0,800;0,342
1,69;910;0,800;0,343
1,70;913;0,800;0,344
1,70;915;0,800;0,345
1,70;919;0,800;0,345
1,71;921;0,800;0,346
1,71;923;0,800;0,347
1,72;927;0,800;0,348
1,72;929;0,800;0,349
1,73;932;0,800;0,350
1,73;935;0,800;0,351
1,73;937;0,800;0,351
1,74;940;0,800;0,352
1,74;942;0,800;0,353
1,75;946;0,800;0,354
1,75;948;0,800;0,355
1,75;952;0,800;0,356
1,76;954;0,800;0,356
1,76;956;0,800;0,357
1,77;958;0,800;0,358
1,77;961;0,800;0,359
1,78;964;0,800;0,360
1,78;967;0,800;0,361
1,78;970;0,800;0,362
1,79;972;0,800;0,362
1,79;975;0,800;0,363
1,80;977;0,800;0,364
1,80;979;0,800;0,365
1,81;982;0,800;0,366
1,81;984;0,800;0,367
1,81;987;0,800;0,367
1,82;991;0,800;0,368
1,82;994;0,800;0,369
1,83;996;0,800;0,370
1,83;999;0,800;0,371
1,84;1000;0,800;0,372
1,84;1000;0,800;0,372
1,84;1010;0,800;0,373
1,85;1010;0,800;0,374
1,85;1010;0,800;0,375
1,86;1010;0,800;0,376
1,86;1020;0,800;0,377
1,86;1020;0,800;0,378
1,87;1020;0,800;0,378
1,87;1030;0,800;0,379
1,88;1030;0,800;0,380
1,88;1030;0,800;0,381
1,89;1030;0,800;0,382
1,89;1040;0,800;0,383
1,89;1040;0,800;0,383
1,90;1040;0,800;0,384
1,90;1040;0,800;0,385
1,91;1050;0,800;0,386
1,91;1050;0,800;0,387
1,92;1050;0,800;0,388
1,92;1050;0,800;0,389
1,92;1060;0,800;0,389
1,93;1060;0,800;0,390
1,93;1060;0,800;0,391
1,94;1060;0,800;0,392
1,94;1070;0,800;0,393
1,95;1070;0,800;0,394
1,95;1070;0,800;0,394
1,95;1080;0,800;0,395
1,96;1080;0,800;0,396
1,96;1080;0,800;0,397
1,97;1080;0,800;0,398
1,97;1090;0,800;0,399
1,97;1090;0,800;0,400
1,98;1090;0,800;0,400
1,98;1090;0,800;0,401
1,99;1100;0,800;0,402
1,99;1100;0,800;0,403
2,00;1100;0,800;0,404
2,00;1100;0,800;0,405
2,00;1110;0,800;0,405
2,01;1110;0,800;0,406
2,01;1110;0,800;0,407
2,02;1120;0,800;0,408
2,02;1120;0,800;0,409
2,03;1120;0,800;0,410
2,03;1120;0,800;0,411
2,03;1120;0,800;0,411
2,04;1130;0,800;0,412
2,04;1130;0,800;0,413
2,05;1130;0,800;0,414
2,05;1140;0,800;0,415
2,06;1140;0,800;0,416
2,06;1140;0,800;0,416
2,06;1140;0,800;0,417
2,07;1150;0,800;0,418
2,07;1150;0,800;0,419
2,08;1150;0,800;0,420
2,08;1150;0,800;0,421
2,08;1160;0,800;0,422
2,09;1160;0,800;0,422
2,09;1160;0,800;0,423
2,10;1160;0,800;0,424
2,10;1170;0,800;0,425
2,11;1170;0,800;0,426
2,11;1170;0,800;0,427
2,11;1170;0,800;0,427
2,12;1180;0,800;0,428
2,12;1180;0,800;0,429
2,13;1180;0,800;0,430
2,13;1180;0,800;0,431
2,14;1190;0,800;0,432
2,14;1190;0,800;0,433
2,14;1190;0,800;0,433
2,15;1200;0,800;0,434
2,15;1200;0,800;0,435
2,16;1200;0,800;0,436
2,16;1200;0,800;0,437
2,17;1210;0,800;0,438
2,17;1210;0,800;0,438
2,17;1210;0,800;0,439
2,18;1210;0,800;0,440
2,18;1210;0,800;0,441
2,19;1220;0,800;0,442
2,19;1220;0,800;0,443
2,19;1220;0,800;0,444
2,20;1230;0,800;0,444
2,20;1230;0,800;0,445
2,21;1230;0,800;0,446
2,21;1230;0,800;0,447
2,22;1240;0,800;0,448
2,22;1240;0,800;0,449
2,22;1240;0,800;0,449
2,23;1240;0,800;0,450
2,23;1250;0,800;0,451
2,24;1250;0,800;0,452
2,24;1250;0,800;0,453
2,25;1250;0,800;0,454
2,25;1260;0,800;0,455
2,25;1260;0,800;0,455
2,26;1260;0,800;0,456
2,26;1260;0,800;0,457
2,27;1270;0,800;0,458
2,27;1270;0,800;0,459
2,28;1270;0,800;0,460
2,28;1270;0,800;0,460
2,28;1280;0,800;0,461
2,29;1280;0,800;0,462
2,29;1280;0,800;0,463
2,30;1280;0,800;0,464
2,30;1290;0,800;0,465
2,30;1290;0,800;0,466
2,31;1290;0,800;0,466
2,31;1290;0,800;0,467
2,32;1300;0,800;0,468
2,32;1300;0,800;0,469
2,33;1300;0,800;0,470
2,33;1300;0,800;0,471
2,33;1310;0,800;0,471
2,34;1310;0,800;0,472
2,34;1310;0,800;0,473
2,35;1310;0,800;0,474
2,35;1320;0,800;0,475
2,36;1320;0,800;0,476
2,36;1320;0,800;0,477
2,36;1320;0,800;0,477
2,37;1330;0,800;0,478
2,37;1330;0,800;0,479
2,38;1330;0,800;0,480
2,38;1330;0,800;0,481
2,38;1340;0,800;0,482
2,39;1340;0,800;0,482
2,39;1340;0,800;0,483
2,40;1340;0,800;0,484
2,40;1350;0,800;0,485
2,41;1350;0,800;0,486
2,41;1350;0,800;0,487
2,41;1350;0,800;0,488
2,42;1360;0,800;0,488
2,42;1360;0,800;0,489
2,43;1360;0,800;0,490
2,43;1360;0,800;0,491
2,44;1370;0,800;0,492
2,44;1370;0,800;0,493
2,44;1370;0,800;0,493
2,45;1370;0,800;0,494
2,45;1380;0,800;0,495
2,46;1380;0,800;0,496
2,46;1380;0,800;0,497
2,47;1380;0,800;0,498
2,47;1390;0,800;0,499
2,47;1390;0,800;0,499
2,48;1390;0,800;0,500
2,48;1390;0,800;0,501
2,49;1400;0,800;0,502
2,49;1400;0,800;0,503
2,49;1400;0,800;0,504
2,50;1400;0,800;0,504
2,50;1400;0,800;0,505
2,51;1410;0,800;0,506
2,51;1410;0,800;0,507
2,52;1410;0,800;0,508
2,52;1410;0,800;0,509
2,52;1420;0,800;0,510
2,53;1420;0,800;0,510
2,53;1420;0,800;0,511
2,54;1420;0,800;0,512
2,54;1430;0,800;0,513
2,55;1430;0,800;0,514
2,55;1430;0,800;0,515
2,55;1430;0,800;0,515
2,56;1440;0,800;0,516
2,56;1440;0,800;0,517
2,57;1440;0,800;0,518
2,57;1440;0,800;0,519
2,58;1450;0,800;0,520
2,58;1450;0,800;0,521
2,58;1450;0,800;0,521
2,59;1450;0,800;0,522
2,59;1460;0,800;0,523
2,60;1460;0,800;0,524
2,60;1460;0,800;0,525
2,61;1460;0,800;0,526
2,61;1470;0,800;0,526
2,61;1470;0,800;0,527
2,62;1470;0,800;0,528
2,62;1470;0,800;0,529
2,63;1470;0,800;0,530
2,63;1480;0,800;0,531
2,63;1480;0,800;0,532
2,64;1480;0,800;0,532
2,64;1480;0,800;0,533
2,65;1490;0,800;0,534
2,65;1490;0,800;0,535
2,66;1490;0,800;0,536
2,66;1490;0,800;0,537
2,66;1500;0,800;0,537
2,67;1500;0,800;0,538
2,67;1500;0,800;0,539
2,68;1500;0,800;0,540
2,68;1500;0,800;0,541
2,69;1510;0,800;0,542
2,69;1510;0,800;0,543
2,69;1510;0,800;0,543
2,70;1510;0,800;0,544
2,70;1520;0,800;0,545
2,71;1520;0,800;0,546
2,71;1520;0,800;0,547
2,71;1520;0,800;0,548
2,72;1530;0,800;0,548
2,72;1530;0,800;0,549
2,73;1530;0,800;0,550
2,73;1530;0,800;0,551
2,74;1540;0,800;0,552
2,74;1540;0,800;0,553
2,74;1540;0,800;0,554
2,75;1540;0,800;0,554
2,75;1540;0,800;0,555
2,76;1550;0,800;0,556
2,76;1550;0,800;0,557
2,77;1550;0,800;0,558
2,77;1550;0,800;0,559
2,77;1560;0,800;0,559
2,78;1560;0,800;0,560
2,78;1560;0,800;0,561
2,79;1560;0,800;0,562
2,79;1570;0,800;0,563
2,80;1570;0,800;0,564
2,80;1570;0,800;0,565
2,80;1570;0,800;0,565
2,81;1570;0,800;0,566
2,81;1580;0,800;0,567
2,82;1580;0,800;0,568
2,82;1580;0,800;0,569
2,83;1580;0,800;0,570
2,83;1590;0,800;0,570
2,83;1590;0,800;0,571
2,84;1590;0,800;0,572
2,84;1590;0,800;0,573
2,85;1590;0,800;0,574
2,85;1600;0,800;0,575
2,85;1600;0,800;0,576
2,86;1600;0,800;0,576
2,86;1600;0,800;0,577
2,87;1610;0,800;0,578
2,87;1610;0,800;0,579
2,88;1610;0,800;0,580
2,88;1610;0,800;0,581
2,88;1610;0,800;0,581
2,89;1620;0,800;0,582
2,89;1620;0,800;0,583
2,90;1620;0,800;0,584
2,90;1620;0,800;0,585
2,90;1630;0,800;0,586
2,91;1630;0,800;0,587
2,91;1630;0,800;0,587
2,92;1630;0,800;0,588
2,92;1640;0,800;0,589
2,93;1640;0,800;0,590
2,93;1640;0,800;0,591
2,94;1640;0,800;0,592
2,94;1640;0,800;0,592
2,94;1650;0,800;0,593
2,95;1650;0,800;0,594
2,95;1650;0,800;0,595
2,96;1650;0,800;0,596
2,96;1650;0,800;0,597
2,96;1660;0,800;0,598
2,97;1660;0,800;0,598
2,97;1660;0,800;0,599
2,98;1660;0,800;0,600
2,98;1670;0,800;0,601
2,99;1670;0,800;0,602
2,99;1670;0,800;0,603
2,99;1670;0,800;0,603
3,00;1670;0,800;0,604
3,00;1680;0,800;0,605
3,01;1680;0,800;0,606
3,01;1680;0,800;0,607
3,02;1680;0,800;0,608
3,02;1680;0,800;0,609
3,02;1690;0,800;0,609
3,03;1690;0,800;0,610
3,03;1690;0,800;0,611
3,04;1690;0,800;0,612
3,04;1700;0,800;0,613
3,04;1700;0,800;0,614
3,05;1700;0,800;0,614
3,05;1700;0,800;0,615
3,06;1700;0,800;0,616
3,06;1710;0,800;0,617
3,07;1710;0,800;0,618
3,07;1710;0,800;0,619
3,07;1710;0,800;0,620
3,08;1720;0,800;0,620
3,08;1720;0,800;0,621
3,09;1720;0,800;0,622
3,09;1720;0,800;0,623
3,10;1720;0,800;0,624
3,10;1730;0,800;0,625
3,10;1730;0,800;0,625
3,11;1730;0,800;0,626
3,11;1730;0,800;0,627
3,12;1730;0,800;0,628
3,12;1740;0,800;0,629
3,13;1740;0,800;0,630
3,13;1740;0,800;0,631
3,13;1740;0,800;0,631
3,14;1740;0,800;0,632
3,14;1750;0,800;0,633
3,15;1750;0,800;0,634
3,15;1750;0,800;0,635
3,15;1750;0,800;0,636
3,16;1760;0,800;0,636
3,16;1760;0,800;0,637
3,17;1760;0,800;0,638
3,17;1760;0,800;0,639
3,18;1760;0,800;0,640
3,18;1770;0,800;0,641
3,18;1770;0,800;0,642
3,19;1770;0,800;0,642
3,19;1770;0,800;0,643
3,20;1770;0,800;0,644
3,20;1780;0,800;0,645
3,21;1780;0,800;0,646
3,21;1780;0,800;0,647
3,21;1780;0,800;0,647
3,22;1780;0,800;0,648
3,22;1790;0,800;0,649
3,23;1790;0,800;0,650
3,23;1790;0,800;0,651
3,24;1790;0,800;0,652
3,24;1800;0,800;0,653
3,24;1800;0,800;0,653
3,25;1800;0,800;0,654
3,25;1800;0,800;0,655
3,26;1800;0,800;0,656
3,26;1810;0,800;0,657
3,27;1810;0,800;0,658
3,27;1810;0,800;0,658
3,27;1810;0,800;0,659
3,28;1820;0,800;0,660
3,28;1820;0,800;0,661
3,29;1820;0,800;0,662
3,29;1820;0,800;0,663
3,29;1820;0,800;0,664
3,30;1830;0,800;0,664
3,30;1830;0,800;0,665
3,31;1830;0,800;0,666
3,31;1830;0,800;0,667
3,32;1830;0,800;0,668
3,32;1840;0,800;0,669
3,32;1840;0,800;0,669
3,33;1840;0,800;0,670
3,33;1840;0,800;0,671
3,34;1840;0,800;0,672
3,34;1840;0,800;0,673
3,35;1850;0,800;0,674
3,35;1850;0,800;0,674
3,35;1850;0,800;0,675
3,36;1850;0,800;0,676
3,36;1850;0,800;0,677
3,37;1860;0,800;0,678
3,37;1860;0,800;0,679
3,38;1860;0,800;0,680
3,38;1860;0,800;0,680
3,38;1860;0,800;0,681
3,39;1870;0,800;0,682
3,39;1870;0,800;0,683
3,40;1870;0,800;0,684
3,40;1870;0,800;0,685
3,40;1870;0,800;0,685
3,41;1880;0,800;0,686
3,41;1880;0,800;0,687
3,42;1880;0,800;0,688
3,42;1880;0,800;0,689
3,43;1880;0,800;0,690
3,43;1890;0,800;0,691
3,43;1890;0,800;0,691
3,44;1890;0,800;0,692
3,44;1890;0,800;0,693
3,45;1890;0,800;0,694
3,45;1900;0,800;0,695
3,46;1900;0,800;0,696
3,46;1900;0,800;0,696
3,46;1900;0,800;0,697
3,47;1900;0,800;0,698
3,47;1900;0,800;0,699
3,48;1910;0,800;0,700
3,48;1910;0,800;0,701
3,49;1910;0,800;0,702
3,49;1910;0,800;0,702
3,49;1910;0,800;0,703
3,50;1920;0,800;0,704
3,50;1920;0,800;0,705
3,51;1920;0,800;0,706
3,51;1920;0,800;0,707
3,51;1920;0,800;0,707
3,52;1930;0,800;0,708
3,52;1930;0,800;0,709
3,53;1930;0,800;0,710
3,53;1930;0,800;0,711
3,54;1930;0,800;0,712
3,54;1940;0,800;0,713
3,54;1940;0,800;0,713
3,55;1940;0,800;0,714
3,55;1940;0,800;0,715
3,56;1940;0,800;0,716
3,56;1940;0,800;0,717
3,57;1950;0,800;0,718
3,57;1950;0,800;0,718
3,57;1950;0,800;0,719
3,58;1950;0,800;0,720
3,58;1950;0,800;0,721
3,59;1950;0,800;0,722
3,59;1960;0,800;0,723
3,59;1960;0,800;0,724
3,60;1960;0,800;0,724
3,60;1960;0,800;0,725
3,61;1960;0,800;0,726
3,62;1970;0,800;0,728
3,62;1970;0,800;0,728
3,62;1970;0,800;0,729
3,62;1970;0,800;0,729
3,63;1970;0,800;0,730
3,63;1970;0,800;0,731
3,64;1980;0,800;0,732
3,64;1980;0,800;0,733
3,64;1980;0,800;0,734
3,65;1980;0,800;0,734
3,65;1980;0,800;0,735
3,66;1990;0,800;0,736
3,66;1990;0,800;0,737
3,66;1990;0,800;0,738
3,67;1990;0,800;0,739
3,67;1990;0,800;0,739
3,68;1990;0,800;0,740
3,68;2000;0,800;0,741
3,69;2000;0,800;0,742
3,69;2000;0,800;0,743
3,69;2000;0,800;0,744
3,70;2000;0,800;0,744
3,70;2010;0,800;0,745
3,71;2010;0,800;0,746
3,71;2010;0,800;0,747
3,72;2010;0,800;0,748
3,72;2010;0,800;0,748
3,72;2010;0,800;0,749
3,73;2020;0,800;0,750
3,73;2020;0,800;0,751
3,74;2020;0,800;0,752
3,74;2020;0,800;0,753
3,74;2020;0,800;0,753
3,75;2020;0,800;0,754
3,75;2030;0,800;0,755
3,76;2030;0,800;0,756
3,76;2030;0,800;0,757
3,76;2030;0,800;0,758
3,77;2030;0,800;0,758
3,77;2030;0,800;0,759
3,78;2040;0,800;0,760
3,78;2040;0,800;0,761
3,78;2040;0,800;0,762
3,79;2040;0,800;0,763
3,79;2040;0,800;0,763
3,80;2040;0,800;0,764
3,80;2050;0,800;0,765
3,81;2050;0,800;0,766
3,81;2050;0,800;0,767
3,81;2050;0,800;0,768
3,82;2050;0,800;0,768
3,82;2050;0,800;0,769
3,83;2060;0,800;0,770
3,83;2060;0,800;0,771
3,83;2060;0,800;0,772
3,84;2060;0,800;0,772
3,84;2060;0,800;0,773
3,85;2060;0,800;0,774
3,85;2070;0,800;0,775
3,86;2070;0,800;0,776
3,86;2070;0,800;0,777
3,86;2070;0,800;0,777
3,87;2070;0,800;0,778
3,87;2080;0,800;0,779
3,88;2080;0,800;0,780
3,88;2080;0,800;0,781
3,88;2080;0,800;0,782
3,89;2080;0,800;0,782
3,89;2080;0,800;0,783
3,90;2080;0,800;0,784
3,90;2090;0,800;0,785
3,91;2090;0,800;0,786
3,91;2090;0,800;0,787
3,91;2090;0,800;0,787
3,92;2090;0,800;0,788
3,92;2090;0,800;0,789
3,93;2100;0,800;0,790
3,93;2100;0,800;0,791
3,93;2100;0,800;0,792
3,94;2100;0,800;0,792
3,94;2100;0,800;0,793
3,95;2100;0,800;0,794
3,95;2100;0,800;0,795
3,95;2110;0,800;0,796
3,96;2110;0,800;0,796
3,96;2110;0,800;0,797
3,97;2110;0,800;0,798
3,97;2110;0,800;0,799
3,98;2120;0,800;0,800
3,98;2120;0,800;0,801
3,98;2120;0,800;0,801
3,99;2120;0,800;0,802
3,99;2120;0,800;0,803
4,00;2120;0,800;0,804
4,00;2120;0,800;0,805
4,00;2130;0,800;0,806
4,01;2130;0,800;0,806
4,01;2130;0,800;0,807
4,02;2130;0,800;0,808
4,02;2130;0,800;0,809
4,03;2130;0,800;0,810
4,03;2130;0,800;0,811
4,03;2140;0,800;0,811
4,04;2140;0,800;0,812
4,04;2140;0,800;0,813
4,05;2140;0,800;0,814
4,05;2140;0,800;0,815
4,05;2140;0,800;0,816
4,06;2150;0,800;0,816
4,06;2150;0,800;0,817
4,07;2150;0,800;0,818
4,07;2150;0,800;0,819
4,08;2150;0,800;0,820
4,08;2150;0,800;0,821
4,08;2160;0,800;0,821
4,09;2160;0,800;0,822
4,09;2160;0,800;0,823
4,10;2160;0,800;0,824
4,10;2160;0,800;0,825
4,10;2160;0,800;0,825
4,11;2160;0,800;0,826
4,11;2170;0,800;0,827
4,12;2170;0,800;0,828
4,12;2170;0,800;0,829
4,12;2170;0,800;0,830
4,13;2170;0,800;0,830
4,13;2170;0,800;0,831
4,14;2170;0,800;0,832
4,14;2180;0,800;0,833
4,15;2180;0,800;0,834
4,15;2180;0,800;0,835
4,15;2180;0,800;0,835
4,16;2180;0,800;0,836
4,16;2180;0,800;0,837
4,17;2180;0,800;0,838
4,17;2190;0,800;0,839
4,17;1460;0,800;0,840
4,18;3,33;0,800;0,841